[2024-04-23T17:57:32.452+0000] {task_context_logger.py:104} ERROR - Executor reports task instance <TaskInstance: nombre_del_dag.tarea_mi_funcion manual__2024-04-23T17:42:59.174615+00:00 [queued]> finished (failed) although the task says it's queued. (Info: None) Was the task killed externally?
