[2024-04-23T17:47:46.392+0000] {local_task_job_runner.py:120} INFO - ::group::Pre task execution logs
[2024-04-23T17:47:46.567+0000] {taskinstance.py:2073} INFO - Dependencies all met for dep_context=non-requeueable deps ti=<TaskInstance: nombre_del_dag.tarea_mi_funcion manual__2024-04-23T17:42:59.174615+00:00 [queued]>
[2024-04-23T17:47:46.702+0000] {taskinstance.py:2073} INFO - Dependencies all met for dep_context=requeueable deps ti=<TaskInstance: nombre_del_dag.tarea_mi_funcion manual__2024-04-23T17:42:59.174615+00:00 [queued]>
[2024-04-23T17:47:46.749+0000] {taskinstance.py:2303} INFO - Starting attempt 1 of 2
[2024-04-23T17:47:46.944+0000] {taskinstance.py:2327} INFO - Executing <Task(PythonOperator): tarea_mi_funcion> on 2024-04-23 17:42:59.174615+00:00
[2024-04-23T17:47:47.091+0000] {standard_task_runner.py:90} INFO - Running: ['***', 'tasks', 'run', 'nombre_del_dag', 'tarea_mi_funcion', 'manual__2024-04-23T17:42:59.174615+00:00', '--job-id', '364', '--raw', '--subdir', 'DAGS_FOLDER/P3.py', '--cfg-path', '/tmp/tmprweg7pzv']
[2024-04-23T17:47:47.252+0000] {standard_task_runner.py:91} INFO - Job 364: Subtask tarea_mi_funcion
[2024-04-23T17:47:46.989+0000] {warnings.py:110} WARNING - /home/***/.local/lib/python3.12/site-packages/***/task/task_runner/standard_task_runner.py:61: DeprecationWarning: This process (pid=77) is multi-threaded, use of fork() may lead to deadlocks in the child.
  pid = os.fork()

[2024-04-23T17:47:47.315+0000] {standard_task_runner.py:63} INFO - Started process 91 to run task
[2024-04-23T17:47:48.380+0000] {task_command.py:426} INFO - Running <TaskInstance: nombre_del_dag.tarea_mi_funcion manual__2024-04-23T17:42:59.174615+00:00 [running]> on host 26fbc25bb53c
[2024-04-23T17:47:49.231+0000] {taskinstance.py:2644} INFO - Exporting env vars: AIRFLOW_CTX_DAG_OWNER='tu_nombre' AIRFLOW_CTX_DAG_ID='nombre_del_dag' AIRFLOW_CTX_TASK_ID='tarea_mi_funcion' AIRFLOW_CTX_EXECUTION_DATE='2024-04-23T17:42:59.174615+00:00' AIRFLOW_CTX_TRY_NUMBER='1' AIRFLOW_CTX_DAG_RUN_ID='manual__2024-04-23T17:42:59.174615+00:00'
[2024-04-23T17:47:49.242+0000] {taskinstance.py:430} INFO - ::endgroup::
[2024-04-23T17:47:49.716+0000] {taskinstance.py:441} INFO - ::group::Post task execution logs
[2024-04-23T17:47:49.877+0000] {taskinstance.py:2890} ERROR - Task failed with exception
Traceback (most recent call last):
  File "/home/airflow/.local/lib/python3.12/site-packages/airflow/models/taskinstance.py", line 465, in _execute_task
    result = _execute_callable(context=context, **execute_callable_kwargs)
             ^^^^^^^^^^^^^^^^^^^^^^^^^^^^^^^^^^^^^^^^^^^^^^^^^^^^^^^^^^^^^
  File "/home/airflow/.local/lib/python3.12/site-packages/airflow/models/taskinstance.py", line 432, in _execute_callable
    return execute_callable(context=context, **execute_callable_kwargs)
           ^^^^^^^^^^^^^^^^^^^^^^^^^^^^^^^^^^^^^^^^^^^^^^^^^^^^^^^^^^^^
  File "/home/airflow/.local/lib/python3.12/site-packages/airflow/models/baseoperator.py", line 400, in wrapper
    return func(self, *args, **kwargs)
           ^^^^^^^^^^^^^^^^^^^^^^^^^^^
  File "/home/airflow/.local/lib/python3.12/site-packages/airflow/operators/python.py", line 235, in execute
    return_value = self.execute_callable()
                   ^^^^^^^^^^^^^^^^^^^^^^^
  File "/home/airflow/.local/lib/python3.12/site-packages/airflow/operators/python.py", line 252, in execute_callable
    return self.python_callable(*self.op_args, **self.op_kwargs)
           ^^^^^^^^^^^^^^^^^^^^^^^^^^^^^^^^^^^^^^^^^^^^^^^^^^^^^
  File "/opt/airflow/plugins/Script.py", line 8, in ETL
    coordinates = [(city, coord[0], coord[1]) for city, coord in cities_coordinates.items()]
                                                                 ^^^^^^^^^^^^^^^^^^
NameError: name 'cities_coordinates' is not defined
[2024-04-23T17:47:50.106+0000] {taskinstance.py:1205} INFO - Marking task as UP_FOR_RETRY. dag_id=nombre_del_dag, task_id=tarea_mi_funcion, execution_date=20240423T174259, start_date=20240423T174746, end_date=20240423T174750
[2024-04-23T17:47:50.315+0000] {standard_task_runner.py:110} ERROR - Failed to execute job 364 for task tarea_mi_funcion (name 'cities_coordinates' is not defined; 91)
[2024-04-23T17:47:50.486+0000] {local_task_job_runner.py:240} INFO - Task exited with return code 1
[2024-04-23T17:47:50.976+0000] {taskinstance.py:3482} INFO - 0 downstream tasks scheduled from follow-on schedule check
[2024-04-23T17:47:51.081+0000] {local_task_job_runner.py:222} INFO - ::endgroup::
