[2024-04-14T20:34:31.312+0000] {task_context_logger.py:104} ERROR - Executor reports task instance <TaskInstance: m_dag_ejecutar.ejecutar_script_ manual__2024-04-14T20:34:29.747858+00:00 [queued]> finished (failed) although the task says it's queued. (Info: None) Was the task killed externally?
