[2024-04-18T12:06:06.168+0000] {task_context_logger.py:104} ERROR - Executor reports task instance <TaskInstance: m_dag_ejecutaapt.ejecutar_script_ scheduled__2024-04-17T00:00:00+00:00 [queued]> finished (failed) although the task says it's queued. (Info: None) Was the task killed externally?
