[2024-04-15T23:40:55.299+0000] {local_task_job_runner.py:120} INFO - ::group::Pre task execution logs
[2024-04-15T23:40:55.661+0000] {taskinstance.py:2073} INFO - Dependencies all met for dep_context=non-requeueable deps ti=<TaskInstance: m_dag_ejecut8.ejecutar_script_python scheduled__2024-04-12T00:00:00+00:00 [queued]>
[2024-04-15T23:40:55.920+0000] {taskinstance.py:2073} INFO - Dependencies all met for dep_context=requeueable deps ti=<TaskInstance: m_dag_ejecut8.ejecutar_script_python scheduled__2024-04-12T00:00:00+00:00 [queued]>
[2024-04-15T23:40:55.925+0000] {taskinstance.py:2303} INFO - Starting attempt 1 of 2
[2024-04-15T23:40:58.126+0000] {taskinstance.py:2327} INFO - Executing <Task(PythonOperator): ejecutar_script_python> on 2024-04-12 00:00:00+00:00
[2024-04-15T23:40:59.095+0000] {warnings.py:110} WARNING - /home/***/.local/lib/python3.12/site-packages/***/task/task_runner/standard_task_runner.py:61: DeprecationWarning: This process (pid=183) is multi-threaded, use of fork() may lead to deadlocks in the child.
  pid = os.fork()

[2024-04-15T23:40:59.844+0000] {standard_task_runner.py:63} INFO - Started process 198 to run task
[2024-04-15T23:41:00.755+0000] {standard_task_runner.py:90} INFO - Running: ['***', 'tasks', 'run', 'm_dag_ejecut8', 'ejecutar_script_python', 'scheduled__2024-04-12T00:00:00+00:00', '--job-id', '234', '--raw', '--subdir', 'DAGS_FOLDER/Prueba.py', '--cfg-path', '/tmp/tmpw6o2gxmm']
[2024-04-15T23:41:01.112+0000] {standard_task_runner.py:91} INFO - Job 234: Subtask ejecutar_script_python
[2024-04-15T23:41:03.885+0000] {task_command.py:426} INFO - Running <TaskInstance: m_dag_ejecut8.ejecutar_script_python scheduled__2024-04-12T00:00:00+00:00 [running]> on host b67ce4676396
[2024-04-15T23:41:05.147+0000] {taskinstance.py:2644} INFO - Exporting env vars: AIRFLOW_CTX_DAG_OWNER='usuario' AIRFLOW_CTX_DAG_ID='m_dag_ejecut8' AIRFLOW_CTX_TASK_ID='ejecutar_script_python' AIRFLOW_CTX_EXECUTION_DATE='2024-04-12T00:00:00+00:00' AIRFLOW_CTX_TRY_NUMBER='1' AIRFLOW_CTX_DAG_RUN_ID='scheduled__2024-04-12T00:00:00+00:00'
[2024-04-15T23:41:05.152+0000] {taskinstance.py:430} INFO - ::endgroup::
[2024-04-15T23:41:05.192+0000] {logging_mixin.py:188} INFO - Error al ejecutar el script: [Errno 2] No such file or directory: '/opt/Prueba2.py'
[2024-04-15T23:41:05.197+0000] {python.py:237} INFO - Done. Returned value was: None
[2024-04-15T23:41:05.205+0000] {taskinstance.py:441} INFO - ::group::Post task execution logs
[2024-04-15T23:41:05.224+0000] {taskinstance.py:1205} INFO - Marking task as SUCCESS. dag_id=m_dag_ejecut8, task_id=ejecutar_script_python, execution_date=20240412T000000, start_date=20240415T234055, end_date=20240415T234105
[2024-04-15T23:41:05.382+0000] {local_task_job_runner.py:240} INFO - Task exited with return code 0
[2024-04-15T23:41:05.463+0000] {taskinstance.py:3482} INFO - 0 downstream tasks scheduled from follow-on schedule check
[2024-04-15T23:41:05.509+0000] {local_task_job_runner.py:222} INFO - ::endgroup::
