[2024-04-23T17:47:53.228+0000] {local_task_job_runner.py:120} INFO - ::group::Pre task execution logs
[2024-04-23T17:47:53.757+0000] {taskinstance.py:2073} INFO - Dependencies all met for dep_context=non-requeueable deps ti=<TaskInstance: nombre_del_dag.tarea_mi_funcion manual__2024-04-23T12:21:10.779103+00:00 [queued]>
[2024-04-23T17:47:53.945+0000] {taskinstance.py:2073} INFO - Dependencies all met for dep_context=requeueable deps ti=<TaskInstance: nombre_del_dag.tarea_mi_funcion manual__2024-04-23T12:21:10.779103+00:00 [queued]>
[2024-04-23T17:47:53.958+0000] {taskinstance.py:2303} INFO - Starting attempt 1 of 2
[2024-04-23T17:47:54.239+0000] {taskinstance.py:2327} INFO - Executing <Task(PythonOperator): tarea_mi_funcion> on 2024-04-23 12:21:10.779103+00:00
[2024-04-23T17:47:54.349+0000] {warnings.py:110} WARNING - /home/***/.local/lib/python3.12/site-packages/***/task/task_runner/standard_task_runner.py:61: DeprecationWarning: This process (pid=78) is multi-threaded, use of fork() may lead to deadlocks in the child.
  pid = os.fork()

[2024-04-23T17:47:54.377+0000] {standard_task_runner.py:63} INFO - Started process 93 to run task
[2024-04-23T17:47:54.381+0000] {standard_task_runner.py:90} INFO - Running: ['***', 'tasks', 'run', 'nombre_del_dag', 'tarea_mi_funcion', 'manual__2024-04-23T12:21:10.779103+00:00', '--job-id', '366', '--raw', '--subdir', 'DAGS_FOLDER/P3.py', '--cfg-path', '/tmp/tmp_rdqcu02']
[2024-04-23T17:47:54.407+0000] {standard_task_runner.py:91} INFO - Job 366: Subtask tarea_mi_funcion
[2024-04-23T17:47:54.986+0000] {task_command.py:426} INFO - Running <TaskInstance: nombre_del_dag.tarea_mi_funcion manual__2024-04-23T12:21:10.779103+00:00 [running]> on host 26fbc25bb53c
[2024-04-23T17:47:56.067+0000] {taskinstance.py:2644} INFO - Exporting env vars: AIRFLOW_CTX_DAG_OWNER='tu_nombre' AIRFLOW_CTX_DAG_ID='nombre_del_dag' AIRFLOW_CTX_TASK_ID='tarea_mi_funcion' AIRFLOW_CTX_EXECUTION_DATE='2024-04-23T12:21:10.779103+00:00' AIRFLOW_CTX_TRY_NUMBER='1' AIRFLOW_CTX_DAG_RUN_ID='manual__2024-04-23T12:21:10.779103+00:00'
[2024-04-23T17:47:56.071+0000] {taskinstance.py:430} INFO - ::endgroup::
[2024-04-23T17:47:56.212+0000] {taskinstance.py:441} INFO - ::group::Post task execution logs
[2024-04-23T17:47:56.265+0000] {taskinstance.py:2890} ERROR - Task failed with exception
Traceback (most recent call last):
  File "/home/airflow/.local/lib/python3.12/site-packages/airflow/models/taskinstance.py", line 465, in _execute_task
    result = _execute_callable(context=context, **execute_callable_kwargs)
             ^^^^^^^^^^^^^^^^^^^^^^^^^^^^^^^^^^^^^^^^^^^^^^^^^^^^^^^^^^^^^
  File "/home/airflow/.local/lib/python3.12/site-packages/airflow/models/taskinstance.py", line 432, in _execute_callable
    return execute_callable(context=context, **execute_callable_kwargs)
           ^^^^^^^^^^^^^^^^^^^^^^^^^^^^^^^^^^^^^^^^^^^^^^^^^^^^^^^^^^^^
  File "/home/airflow/.local/lib/python3.12/site-packages/airflow/models/baseoperator.py", line 400, in wrapper
    return func(self, *args, **kwargs)
           ^^^^^^^^^^^^^^^^^^^^^^^^^^^
  File "/home/airflow/.local/lib/python3.12/site-packages/airflow/operators/python.py", line 235, in execute
    return_value = self.execute_callable()
                   ^^^^^^^^^^^^^^^^^^^^^^^
  File "/home/airflow/.local/lib/python3.12/site-packages/airflow/operators/python.py", line 252, in execute_callable
    return self.python_callable(*self.op_args, **self.op_kwargs)
           ^^^^^^^^^^^^^^^^^^^^^^^^^^^^^^^^^^^^^^^^^^^^^^^^^^^^^
  File "/opt/airflow/plugins/Script.py", line 8, in ETL
    coordinates = [(city, coord[0], coord[1]) for city, coord in cities_coordinates.items()]
                                                                 ^^^^^^^^^^^^^^^^^^
NameError: name 'cities_coordinates' is not defined
[2024-04-23T17:47:56.627+0000] {taskinstance.py:1205} INFO - Marking task as UP_FOR_RETRY. dag_id=nombre_del_dag, task_id=tarea_mi_funcion, execution_date=20240423T122110, start_date=20240423T174753, end_date=20240423T174756
[2024-04-23T17:47:56.842+0000] {standard_task_runner.py:110} ERROR - Failed to execute job 366 for task tarea_mi_funcion (name 'cities_coordinates' is not defined; 93)
[2024-04-23T17:47:56.995+0000] {local_task_job_runner.py:240} INFO - Task exited with return code 1
[2024-04-23T17:47:57.290+0000] {taskinstance.py:3482} INFO - 0 downstream tasks scheduled from follow-on schedule check
[2024-04-23T17:47:57.343+0000] {local_task_job_runner.py:222} INFO - ::endgroup::
