[2024-04-14T20:35:54.382+0000] {task_context_logger.py:104} ERROR - Executor reports task instance <TaskInstance: m_dag_ejecut4.ejecutar_script_python scheduled__2024-04-13T00:00:00+00:00 [queued]> finished (failed) although the task says it's queued. (Info: None) Was the task killed externally?
