[2024-04-14T20:25:46.448+0000] {task_context_logger.py:104} ERROR - Executor reports task instance <TaskInstance: m_dag_ejecuta.ejecutar_script_ manual__2024-04-13T17:29:19.439115+00:00 [queued]> finished (failed) although the task says it's queued. (Info: None) Was the task killed externally?
