[2024-04-15T23:48:13.626+0000] {task_context_logger.py:104} ERROR - Executor reports task instance <TaskInstance: m_dag_ejecutar.ejecutar_script_python scheduled__2024-04-14T00:00:00+00:00 [queued]> finished (failed) although the task says it's queued. (Info: None) Was the task killed externally?
