[2024-04-14T20:25:44.566+0000] {task_context_logger.py:104} ERROR - Executor reports task instance <TaskInstance: m_dag_ejecuta.ejecutar_script_ scheduled__2024-04-08T00:00:00+00:00 [queued]> finished (failed) although the task says it's queued. (Info: None) Was the task killed externally?
